Workbook

Sheet Site summary sheet
A1: Site ID | B1: Date | C1: GPS N | D1: GPSE | E1: Salmon | F1: AWC? | G1: Comments
A2: V01 | B2: 40722 | E2: n | F2: N | G2: No discharge measurement taken, no GPS coordinates on data sheets
A3: V02 | B3: 40723 | C3: 6620600 | D3: 574374 | E3: y | G3: No densiometer
A4: V03 | B4: 40729 | C4: 6619804 | D4: 573199 | E4: y | G4: No densiometer
A5: V04 | B5: 40730 | C5: 6621345 | D5: 576660 | E5: y | G5: No densiometer
A6: V05 | B6: 40731 | C6: 6624361 | D6: 572317 | E6: y | G6: No densiometer
A7: V06 | B7: 40735 | C7: 6630021 | D7: 583463 | E7: n | F7: N | G7: No densiometer
A8: V07 | B8: 40735 | C8: 6632556 | D8: 578209 | E8: n | G8: Didn't finish form 4
A9: V08 | B9: * | F9: N | G9: No water
A10: V09 | B10: 40736 | C10: 6639833 | D10: 571761 | E10: y | F10: N | G10: 2.5 hour travel time + 0.5 hour hike in, no GPS coordinates on data sheet, need from GPS unit_data from Google Earth and site maps, nominated for AWC
A11: V10 | B11: * | F11: N | G11: Must have permission from landowner for access, even then it will be challenging
A12: V11 | B12: * | G12: Not accessible, locked gate
A13: V12 | B13: 40738 | E13: n | F13: N | G13: No YSI or GPS coords
A14: V13 | B14: 40739 | C14: 6658334 | D14: 596086 | E14: n | F14: N | G14: No fish
A15: V14 | B15: * | F15: N | G15: Difficult access, must cross mainstem Deep Creek, steep slope
A16: V15 | B16: * | F16: N | G16: No water, Pam's 31 July email reports this site as sampled, no data sheets
A17: V16 | B17: 40745 | C17: 6632183 | D17: 578815 | E17: n | F17: N
A18: V17 | B18: 40743 | C18: 6624177 | D18: 595824 | E18: y | F18: N | G18: easy access, coho found, nominated for AWC
A19: V18 | B19: 40750 | C19: 6624259 | D19: 596179 | E19: n | F19: N | G19: No GPS point at G, batteries died
A20: V19 | B20: 40746 | C20: 6639411 | D20: 580932 | E20: n | F20: N
A21: V20 | B21: * | G21: Thick willow, could not shock (Pam's email 31 July)
A22: V21 | B22: 40752 | C22: 6641216 | D22: 579857 | E22: y | F22: N | G22: nominated for AWC
A23: V22 | B23: * | F23: N | G23: Attempted on 8/23, site is on hillside, no water. Creek below is heavily brushed, not shock-able
A24: V23 | B24: 40751 | C24: 6635803 | D24: 576873 | E24: n | F24: N
A25: V24 | B25: 40771 | C25: 6621652 | D25: 582745 | E25: y | F25: N | G25: Juvenile CO present, no fish photos, TDN sampled, nominated for AWC
A26: V25 | B26: 40764 | C26: 6644473 | D26: 590649 | E26: n | F26: N
A27: V26 | B27: 40767 | C27: 6649246 | D27: 579591 | E27: n | F27: N | G27: Wheeler access site
A28: V27 | B28: * | F28: N | G28: Too brushy, not fishable (Pam's email 31 Jul)
A29: V28 | B29: 40736 | C29: 6651082 | D29: 599065 | E29: n | F29: N
A30: V29 | B30: * | F30: N | G30: Attempted 8/23, not fishable, thick willow/veg
A31: V30 | B31: 40768 | C31: 6649105 | D31: 581132 | E31: n | F31: N | G31: Wheeler access site, no fish found
A32: V31 | B32: * | F32: N | G32: Not enough flow, marsh
A33: V32 | B33: * | G33: No road
A34: V33 | F34: N | G34: Moved site
A35: V34 | B35: * | F35: N | G35: Access appears off Skyline, not attempted, need imagery
A36: V35 | B36: * | F36: N | G36: Not enough water/flow to sample
A37: V36 | B37: * | F37: N | G37: attempted 8/17, too much willow to sample stream
A38: V37 | B38: * | F38: N | G38: Moved site
A39: V38 | B39: * | F39: N | G39: No road
A40: V39 | B40: * | G40: No road
...

Sheet Form1_Site
D1: GPS | I1: Weather Conditions | N1: IN-SITU Measurements
A2: Site ID | B2: Shed code | C2: Date | D2: Tran A | F2: Tran G | H2: Samplers initials | I2: Cloud Cover | J2: Precip | K2: 24 hr Precip | L2: Air Temp C | M2: Time HH:MM | N2: Water Temp C | O2: SpCond (uS/cm) | P2: DO (mg/L) | Q2: DO (% sat) | R2: Ph
A3: ='Site summary sheet'!A2 -> V01 | B3: SANC | C3: ='Site summary sheet'!B2 -> 40722 | D3: ='Site summary sheet'!C2 -> 0 | E3: ='Site summary sheet'!D2 -> 0 | H3: CW, JM,SH,PK, KB, TN | I3: >75 | J3: LIGHT | K3: Light | M3: 0.43680556 | N3: 5.6 | O3: 38.5
A4: ='Site summary sheet'!A3 -> V02 | B4: SANC | C4: ='Site summary sheet'!B3 -> 40723 | D4: ='Site summary sheet'!C3 -> 6620600 | E4: ='Site summary sheet'!D3 -> 574374 | F4: 6620068 | G4: 574453 | H4: JM, CW, KB | I4: >75 | J4: None | K4: Mod | M4: 0.41666667 | N4: 6.06 | O4: 64 | P4: 13.3 | Q4: 106.9 | R4: 7.11
A5: ='Site summary sheet'!A4 -> V03 | B5: SANC | C5: ='Site summary sheet'!B4 -> 40729 | D5: ='Site summary sheet'!C4 -> 6619804 | E5: ='Site summary sheet'!D4 -> 573199 | F5: 6619712 | G5: 573254 | H5: SB, MC | I5: <5 | J5: None | K5: Light | M5: 0.39375 | N5: 4.9 | O5: 58 | P5: 12.69 | Q5: 99.4 | S5: GPS WAS SET TO DMS NAD 27
A6: ='Site summary sheet'!A5 -> V04 | B6: SANC | C6: ='Site summary sheet'!B5 -> 40730 | D6: ='Site summary sheet'!C5 -> 6621345 | E6: ='Site summary sheet'!D5 -> 576660 | F6: 6621454 | G6: 576665 | H6: DB, MC, JM | I6: >75 | J6: None | K6: None | M6: 0.40069444 | N6: 5.1 | O6: 64.2 | P6: 12.53 | Q6: 98.5
A7: ='Site summary sheet'!A6 -> V05 | B7: NANC | C7: ='Site summary sheet'!B6 -> 40731 | D7: ='Site summary sheet'!C6 -> 6624361 | E7: ='Site summary sheet'!D6 -> 572317 | F7: 6624419 | G7: 572281 | H7: KB, JS, PK | I7: 50-75% | J7: None | K7: None | M7: 0.42361111 | N7: 7.01 | O7: 69 | P7: 13.68 | Q7: 113 | R7: 7.55
A8: ='Site summary sheet'!A7 -> V06 | B8: NANC | C8: ='Site summary sheet'!B7 -> 40735 | D8: ='Site summary sheet'!C7 -> 6630021 | E8: ='Site summary sheet'!D7 -> 583463 | F8: 6630075 | G8: 583540 | H8: DH, MG,JM | I8: >75 | J8: None | K8: Light | M8: 0.43541667 | N8: 6.12 | O8: 59 | P8: 14.38 | Q8: 116.4 | R8: 7.5
A9: ='Site summary sheet'!A8 -> V07 | B9: NANC | C9: ='Site summary sheet'!B8 -> 40735 | D9: ='Site summary sheet'!C8 -> 6632556 | E9: ='Site summary sheet'!D8 -> 578209 | F9: 6632644 | G9: 578194 | H9: PK, JS, KB | I9: >75 | J9: None | K9: None | M9: 0.38541667 | N9: 7.9 | O9: 52.8 | P9: 10.88 | Q9: 93.1
A10: ='Site summary sheet'!A10 -> V09 | B10: STAR | C10: ='Site summary sheet'!B10 -> 40736 | D10: ='Site summary sheet'!C10 -> 6639833 | E10: ='Site summary sheet'!D10 -> 571761 | H10: DH,PK, JS | I10: >75 | J10: LIGHT | K10: Light | L10: 13.21 | N10: 6.53 | O10: 73 | P10: 12.47 | Q10: 101.5 | R10: 7.05
A11: ='Site summary sheet'!A13 -> V12 | B11: DEEP | C11: ='Site summary sheet'!B13 -> 40738 | D11: ='Site summary sheet'!C13 -> 0 | E11: ='Site summary sheet'!D13 -> 0 | H11: DH,PK, JS, JM | I11: 5-25% | J11: None | K11: Light | M11: 0.38541667 | N11: 9.87 | O11: 61 | P11: 10.97 | Q11: 96.4 | R11: 7.54
A12: ='Site summary sheet'!A14 -> V13 | B12: DEEP | C12: ='Site summary sheet'!B14 -> 40739 | D12: ='Site summary sheet'!C14 -> 6658334 | E12: ='Site summary sheet'!D14 -> 596086 | F12: 6658250 | G12: 596088 | H12: DH, PK, JS | I12: <5 | J12: None | K12: None | M12: 0.39583333 | N12: 5.18 | O12: 53 | P12: 12.61 | Q12: 99.3 | R12: 7.44
A13: ='Site summary sheet'!A17 -> V16 | B13: NANC | C13: ='Site summary sheet'!B17 -> 40745 | D13: ='Site summary sheet'!C17 -> 6632183 | E13: ='Site summary sheet'!D17 -> 578815 | F13: 6632149 | G13: 578879 | H13: PK, DH, MC | I13: >75 | J13: Mod | K13: Light | M13: 0.375 | N13: 6.77 | O13: 86 | P13: 11.06 | Q13: 90.6 | R13: 7.69
A14: ='Site summary sheet'!A18 -> V17 | B14: SANC | C14: ='Site summary sheet'!B18 -> 40743 | D14: ='Site summary sheet'!C18 -> 6624177 | E14: ='Site summary sheet'!D18 -> 595824 | H14: TN, JS, MM | I14: <5 | J14: None | K14: None | L14: 11.8 | M14: 0.38680556 | N14: 6.85 | O14: 51 | P14: 11.21 | Q14: 91 | R14: 7.4
A15: ='Site summary sheet'!A19 -> V18 | B15: SANC | C15: ='Site summary sheet'!B19 -> 40750 | D15: ='Site summary sheet'!C19 -> 6624259 | E15: ='Site summary sheet'!D19 -> 596179 | H15: PK, JS, DH | I15: 50-75% | J15: NONE | K15: NONE | M15: 0.41666667 | N15: 6.83 | O15: 56 | P15: 10.04 | Q15: 82.7 | R15: 6.99
A16: ='Site summary sheet'!A20 -> V19 | B16: NANC | C16: ='Site summary sheet'!B20 -> 40746 | D16: ='Site summary sheet'!C20 -> 6639411 | E16: ='Site summary sheet'!D20 -> 580932 | H16: DH, PK, JS | I16: 5-25% | J16: None | K16: Light | M16: 0.39583333 | N16: 6.63 | O16: 60 | P16: 11.17 | Q16: 91.1 | R16: 7.44 | S16: TEMP LOGGER DEPLOYED UNDER BRIDGE, LEFT BAND, RIGHT SID OF BRIDGE DRIVING IN RIGHT
A17: ='Site summary sheet'!A22 -> V21 | B17: NANC | C17: ='Site summary sheet'!B22 -> 40752 | D17: ='Site summary sheet'!C22 -> 6641216 | E17: ='Site summary sheet'!D22 -> 579857 | F17: 6641174 | G17: 579948 | H17: JS, PK, DH | I17: <5 | J17: None | K17: Light | M17: 0.40833333 | N17: 6.55 | O17: 68 | P17: 11.26 | Q17: 92.3 | R17: 7.45
A18: ='Site summary sheet'!A24 -> V23 | B18: NANC | C18: ='Site summary sheet'!B24 -> 40751 | D18: ='Site summary sheet'!C24 -> 6635803 | E18: ='Site summary sheet'!D24 -> 576873 | F18: 6635729 | G18: 576983 | H18: PK, DH, JS | I18: <75 | J18: LIGHT | K18: Mod | M18: 0.39583333 | N18: 5.91 | O18: 70 | P18: 11.44 | Q18: 91.8 | R18: 7.4
A19: ='Site summary sheet'!A25 -> V24 | B19: SANC | C19: ='Site summary sheet'!B25 -> 40771 | D19: ='Site summary sheet'!C25 -> 6621652 | E19: ='Site summary sheet'!D25 -> 582745 | F19: 6621652 | G19: 582819 | H19: TN, JM | I19: 5-25% | J19: None | K19: None | M19: 0.45416667 | N19: 5.7 | O19: 44.5 | P19: 11.89 | Q19: 96.6
A20: ='Site summary sheet'!A26 -> V25 | B20: DEEP | C20: ='Site summary sheet'!B26 -> 40764 | D20: ='Site summary sheet'!C26 -> 6644473 | E20: ='Site summary sheet'!D26 -> 590649 | F20: 6644583 | G20: 590678 | H20: JS, JM | I20: 25-50% | J20: None | K20: Mod | M20: 0.44027778 | N20: 6.9 | O20: 17.8 | P20: 11.79 | Q20: 99.7
A21: ='Site summary sheet'!A27 -> V26 | B21: DEEP | C21: ='Site summary sheet'!B27 -> 40767 | D21: ='Site summary sheet'!C27 -> 6649246 | E21: ='Site summary sheet'!D27 -> 579591 | F21: 6649104 | G21: 581133 | H21: TN, CW, JM | I21: 5-25% | J21: None | K21: None | M21: 0.48680556 | N21: 6.1 | O21: 41.3 | P21: 12.17 | Q21: 98.8
A22: ='Site summary sheet'!A29 -> V28 | B22: DEEP | C22: ='Site summary sheet'!B29 -> 40736 | D22: ='Site summary sheet'!C29 -> 6651082 | E22: ='Site summary sheet'!D29 -> 599065 | F22: 6651019 | G22: 598985 | H22: CW, KB,JM | I22: >75 | J22: LIGHT | K22: Light | M22: 0.43958333 | N22: 5.5 | O22: 45.5 | P22: 11.88 | Q22: 97.5
A23: ='Site summary sheet'!A31 -> V30 | B23: DEEP | C23: ='Site summary sheet'!B31 -> 40768 | D23: ='Site summary sheet'!C31 -> 6649105 | E23: ='Site summary sheet'!D31 -> 581132 | F23: 6649031 | G23: 581149 | H23: TN, JS, JM | I23: 5-25% | J23: None | K23: None | M23: 0.60416667 | N23: 7.9 | O23: 41.7 | P23: 9.97 | Q23: 84.1
A24: ='Site summary sheet'!A42 -> V41 | B24: NANC | C24: ='Site summary sheet'!B42 -> 40756 | D24: ='Site summary sheet'!C42 -> 663137 | E24: ='Site summary sheet'!D42 -> 569717 | F24: 6631225 | G24: 569801 | H24: PK, DH, JS | I24: >75 | J24: None | K24: Light | M24: 0.35416667 | N24: 8.3 | O24: 68 | P24: 10.21 | Q24: 86.8 | R24: 7.19
A25: ='Site summary sheet'!A43 -> V42 | B25: NINI | C25: 40779 | D25: ='Site summary sheet'!C43 -> 6660287 | E25: ='Site summary sheet'!D43 -> 596060 | H25: JF, TN, JK | I25: >75 | J25: None | K25: Mod | N25: 6 | O25: 54.2 | P25: 11.67 | Q25: 96.8 | R25: na
A26: ='Site summary sheet'!A44 -> V43 | B26: NANC | C26: ='Site summary sheet'!B44 -> 40773 | D26: ='Site summary sheet'!C44 -> 6630697 | E26: ='Site summary sheet'!D44 -> 567558 | F26: 663063 | G26: 567474 | H26: TN, JS, JK | I26: >75 | J26: Mod | K26: None | M26: 0.45

Sheet Form2_Fish
A1: Site ID | B1: Date | C1: Samplers initials | D1: Reach | E1: Pass | F1: Species | G1: Length (mm) | H1: Weight (g) | I1: Efisher info | J1: Comment
A2: V43 | B2: 40773 | C2: TN, JS, JK | D2: 0-50 | E2: 1 | F2: CO | G2: 109 | H2: 13 | I2: 255V, 12%, 30Hz
A3: V43 | B3: 40773 | C3: TN, JS, JK | D3: 0-50 | E3: 1 | F3: CO | G3: 47 | H3: 0.8 | I3: 255V, 12%, 30Hz
A4: V43 | B4: 40773 | C4: TN, JS, JK | D4: 0-50 | E4: 1 | F4: CO | G4: 43 | H4: 0.6 | I4: 255V, 12%, 30Hz
A5: V43 | B5: 40773 | C5: TN, JS, JK | D5: 0-50 | E5: 1 | F5: CO | G5: 54 | H5: 1.5 | I5: 255V, 12%, 30Hz
A6: V43 | B6: 40773 | C6: TN, JS, JK | D6: 0-50 | E6: 1 | F6: CO | G6: 46 | H6: 0.5 | I6: 255V, 12%, 30Hz
A7: V43 | B7: 40773 | C7: TN, JS, JK | D7: 0-50 | E7: 1 | F7: CO | G7: 44 | H7: 8 | I7: 255V, 12%, 30Hz
A8: V43 | B8: 40773 | C8: TN, JS, JK | D8: 0-50 | E8: 1 | F8: CO | G8: 36 | H8: 0.3 | I8: 255V, 12%, 30Hz
A9: V43 | B9: 40773 | C9: TN, JS, JK | D9: 0-50 | E9: 1 | F9: CO | G9: 48 | H9: 1 | I9: 255V, 12%, 30Hz
A10: V43 | B10: 40773 | C10: TN, JS, JK | D10: 0-50 | E10: 1 | F10: CO | G10: 47 | H10: 0.8 | I10: 255V, 12%, 30Hz
A11: V43 | B11: 40773 | C11: TN, JS, JK | D11: 0-50 | E11: 1 | F11: CO | G11: 42 | H11: 0.4 | I11: 255V, 12%, 30Hz
A12: V43 | B12: 40773 | C12: TN, JS, JK | D12: 0-50 | E12: 1 | F12: CO | G12: 59 | H12: 2 | I12: 255V, 12%, 30Hz
A13: V43 | B13: 40773 | C13: TN, JS, JK | D13: 0-50 | E13: 1 | F13: CO | G13: 10 | H13: 0.5 | I13: 255V, 12%, 30Hz
... A134: V43 | B134: 40773 | C134: TN, JS, JK | D134: 50-100 | E134: 1 | F134: DV | G134: 132 | H134: 24.5 | I134: 255V, 12%, 30Hz
A135: V43 | B135: 40773 | C135: TN, JS, JK | D135: 50-100 | E135: 1 | F135: DV | G135: 150 | H135: 30+ | I135: 255V, 12%, 30Hz
A136: V43 | B136: 40773 | C136: TN, JS, JK | D136: 50-100 | E136: 1 | F136: 3S | G136: 48 | H136: 0.8 | I136: 255V, 12%, 30Hz
A137: V43 | B137: 40773 | C137: TN, JS, JK | D137: 50-100 | E137: 1 | F137: 3S | G137: 50 | H137: 0.8 | I137: 255V, 12%, 30Hz
A138: V43 | B138: 40773 | C138: TN, JS, JK | D138: 50-100 | E138: 1 | F138: 3S | G138: 46 | H138: 0.6 | I138: 255V, 12%, 30Hz
A139: V43 | B139: 40773 | C139: TN, JS, JK | D139: 50-100 | E139: 2 | F139: CO | G139: 54 | H139: 1.6 | I139: 255V, 12%, 30Hz
A140: V43 | B140: 40773 | C140: TN, JS, JK | D140: 50-100 | E140: 2 | F140: CO | G140: 100 | H140: 11.25 | I140: 255V, 12%, 30Hz
A141: V43 | B141: 40773 | C141: TN, JS, JK | D141: 50-100 | E141: 2 | F141: CO | G141: 104 | H141: 12.5 | I141: 255V, 12%, 30Hz
A142: V43 | B142: 40773 | C142: TN, JS, JK | D142: 50-100 | E142: 2 | F142: CO | G142: 106 | H142: 14 | I142: 255V, 12%, 30Hz
A143: V43 | B143: 40773 | C143: TN, JS, JK | D143: 50-100 | E143: 2 | F143: CO | G143: 103 | H143: 12 | I143: 255V, 12%, 30Hz
A144: V43 | B144: 40773 | C144: TN, JS, JK | D144: 50-100 | E144: 2 | F144: 3S | G144: 44 | H144: 0.4 | I144: 255V, 12%, 30Hz
A145: V43 | B145: 40773 | C145: TN, JS, JK | D145: 50-100 | E145: 2 | F145: 3S | G145: 53 | H145: 1 | I145: 255V, 12%, 30Hz
A146: V43 | B146: 40773 | C146: TN, JS, JK | D146: 50-100 | E146: 2 | F146: 3S | G146: 46 | H146: 0.8 | I146: 255V, 12%, 30Hz
A147: V43 | B147: 40773 | C147: TN, JS, JK | D147: 50-100 | E147: 2 | F147: 3S | G147: 19 | I147: 255V, 12%, 30Hz
A148: V43 | B148: 40773 | C148: TN, JS, JK | D148: 50-100 | E148: 2 | F148: 3S | G148: 52 | H148: 1.2 | I148: 255V, 12%, 30Hz
A149: V43 | B149: 40773 | C149: TN, JS, JK | D149: 50-100 | E149: 2 | F149: DV | G149: 126 | H149: 24.5 | I149: 255V, 12%, 30Hz
A150: V43 | B150: 40773 | C150: TN, JS, JK | D150: 100-150 | E150: 1 | F150: CO | G150: 55 | H150: 1.4 | I150: 255V, 12%, 30Hz
A151: V43 | B151: 40773 | C151: TN, JS, JK | D151: 100-150 | E151: 1 | F151: CO | G151: 102 | H151: 10.5 | I151: 255V, 12%, 30Hz
A152: V43 | B152: 40773 | C152: TN, JS, JK | D152: 100-150 | E152: 1 | F152: CO | G152: 82 | H152: 6.3 | I152: 255V, 12%, 30Hz
A153: V43 | B153: 40773 | C153: TN, JS, JK | D153: 100-150 | E153: 1 | F153: DV | G153: 126 | H153: 21 | I153: 255V, 12%, 30Hz
A154: V43 | B154: 40773 | C154: TN, JS, JK | D154: 100-150 | E154: 1 | F154: CK | G154: 71 | H154: 3.8 | I154: 255V, 12%, 30Hz
A155: V43 | B155: 40773 | C155: TN, JS, JK | D155: 100-150 | E155: 1 | F155: CK | G155: 76 | H155: 5.2 | I155: 255V, 12%, 30Hz
A156: V43 | B156: 40773 | C156: TN, JS, JK | D156: 100-150 | E156: 2 | F156: CO | G156: 91 | H156: 9.75 | I156: 255V, 12%, 30Hz | J156: efisher malfunction on 1st pass 100-150
A157: V43 | B157: 40773 | C157: TN, JS, JK | D157: 100-150 | E157: 2 | F157: CO | G157: 98 | H157: 12 | I157: 255V, 12%, 30Hz
A158: V43 | B158: 40773 | C158: TN, JS, JK | D158: 100-150 | E158: 2 | F158: CO | G158: 56 | H158: 25 | I158: 255V, 12%, 30Hz
A159: V43 | B159: 40773 | C159: TN, JS, JK | D159: 100-150 | E159: 2 | F159: CO | G159: 51 | H159: 2.4 | I159: 255V, 12%, 30Hz
A160: V43 | B160: 40773 | C160: TN, JS, JK | D160: 100-150 | E160: 2 | F160: CO | G160: 102 | H160: 1.75 | I160: 255V, 12%, 30Hz
...

Sheet Form3_PHab
D1: Substrate Cross-section Data | AJ1: Transect Midpoint Thalweg Profile | AQ1: Pools between | AU1: Large Woody Debris | AY1: Note
D2: Left | H2: Left Center | L2: Center | P2: Right Center | T2: Right | X2: Fish Cover/Other | AA2: Canopy Cover (Densiometer) | AE2: Bank/Thalweg Profile | AL2: Substrate | AQ2: Pair | AR2: Length | AS2: Width | AT2: Depth | AU2: Pair | AV2: Diameter (m) | AW2: Length (m) | AX2: Count
A3: Site ID | B3: Date | C3: Transect | D3: Dist LB (m) | E3: Depth (m) | F3: Sz class | G3: Embed % | H3: Dist LB (m) | I3: Depth (m) | J3: Sz class | K3: Embed % | L3: Dist LB (m) | M3: Depth (m) | N3: Sz class | O3: Embed % | P3: Dist LB (m) | Q3: Depth (m) | R3: Sz class | S3: Embed % | T3: Dist LB (m) | U3: Depth (m) | V3: Sz class | W3: Embed % | X3: Filament algae | Y3: Biofilms | Z3: Overhang veg | AA3: Up | AB3: L | AC3: Dwn | AD3: R | AE3: Left undercut (cm) | AF3: Right undercut (cm) | AG3: wetted width (m) | AH3: Thalweg depth (m) | AI3: Thalweg velocity (m/s) | AJ3: Thalweg depth (m) | AK3: Wetted width (m) | AL3: Left | AM3: Left Center | AN3: Center | AO3: Right Center | AP3: Right
A4: V43 | B4: 40773 | C4: G | D4: 0.1 | E4: 0.06 | F4: SA | G4: 100 | H4: 0.36 | I4: 0.11 | J4: SA | K4: 100 | L4: 0.57 | M4: 0.11 | N4: SA | O4: 100 | P4: 1 | Q4: 0.13 | R4: SA | S4: 100 | T4: 1.3 | U4: 0.12 | V4: SA | W4: 100 | X4: 0 | Y4: 0 | Z4: 2 | AA4: 0 | AB4: 0 | AC4: 0 | AD4: 0 | AE4: 0 | AF4: 0 | AG4: 1.38 | AH4: 0.13 | AI4: 0.19
A5: V43 | B5: 40773 | C5: F | D5: 0 | E5: 0.31 | F5: FN | G5: 100 | H5: 0.31 | I5: 0.31 | J5: FN | K5: 100 | L5: 0.64 | M5: 0.31 | N5: FN | O5: 100 | P5: 1 | Q5: 0.15 | R5: WD | S5: 0 | T5: 1.35 | U5: 0.07 | V5: FN | W5: 100 | X5: 0 | Y5: 0 | Z5: 1 | AA5: 0 | AB5: 0 | AC5: 0 | AD5: 0 | AE5: 0 | AF5: 0 | AG5: 1.38 | AH5: 0.31 | AI5: 0.03 | AJ5: 0.24 | AK5: 1.82 | AL5: SA | AM5: FN | AN5: WD | AO5: FN | AP5: FN | AY5: *1: Undercut
A6: V43 | B6: 40773 | C6: E | D6: 0 | G6: *1 | H6: 0.67 | I6: 0.24 | J6: FN | K6: 100 | L6: 1 | M6: 0.38 | N6: GF | O6: 70 | P6: 1.22 | Q6: 0.38 | R6: GF | S6: 70 | T6: 1.39 | U6: 0.36 | V6: GF | W6: 70 | X6: 0 | Y6: 0 | Z6: 2 | AA6: 0 | AB6: 0 | AC6: 15 | AD6: 21 | AE6: 0.37 | AF6: 0 | AG6: 1.39 | AH6: 0.39 | AI6: 0 | AJ6: 0.25 | AK6: 2.38 | AL6: FN | AM6: WD | AN6: FN | AO6: FN | AP6: SA
A7: V43 | B7: 40773 | C7: C | D7: 0.07 | E7: 0.35 | F7: FN | G7: 100 | H7: 0.5 | I7: 0.44 | J7: GF | K7: *2 | L7: 1 | M7: 0.42 | N7: FN | O7: 100 | P7: 1.5 | Q7: 0.34 | R7: FN | S7: 100 | T7: 1.95 | U7: 0.14 | V7: FN | X7: 0 | Y7: 0 | Z7: 1 | AA7: 0 | AB7: 1 | AC7: 0 | AD7: 0 | AE7: 0 | AF7: 17 | AG7: 2.06 | AH7: 0.48 | AI7: 0.04 | AJ7: 0.43 | AK7: 2.24 | AL7: GC | AM7: GC | AN7: GC | AO7: GF | AP7: SA | AY7: *2: No data, no note
A8: V43 | B8: 40773 | C8: D | D8: 0.05 | E8: 0.05 | F8: FN | G8: 100 | H8: 0.59 | I8: 0.2 | J8: FN | K8: 100 | L8: 1.23 | M8: 0.12 | N8: FN | O8: 100 | P8: 1.92 | Q8: 0.06 | R8: FN | S8: 100 | T8: 2.49 | U8: 0.05 | V8: FN | W8: 100 | X8: 0 | Y8: 0 | Z8: 1 | AA8: 0 | AB8: 3 | AC8: 1 | AD8: 0 | AE8: 0 | AF8: 0 | AG8: 2.56 | AH8: 0.2 | AI8: 0.03 | AJ8: 0.17 | AK8: 1.48 | AL8: FN | AM8: GF | AN8: GF | AO8: GF | AP8: FN | AQ8: CD | AR8: 3.24 | AS8: 3.06 | AT8: 0.74
A9: V43 | B9: 40773 | C9: B | D9: 0.05 | E9: 0.01 | F9: SA | G9: 100 | H9: 0.3 | I9: 0.11 | J9: WD | K9: 0 | L9: 0.64 | M9: 0.18 | N9: GC | O9: 20 | P9: 0.93 | Q9: 0.17 | R9: WD | S9: 0 | T9: 0.05 | U9: 0.08 | V9: WD | W9: 0 | X9: 0 | Y9: 0 | Z9: 1 | AA9: 0 | AB9: 4 | AC9: 5 | AD9: 0 | AE9: 0 | AF9: 0 | AG9: 1.23 | AH9: 0.18 | AI9: 0.9 | AJ9: 0.34 | AK9: 1.77 | AL9: SA | AM9: WD | AN9: WD | AO9: GC | AP9: GC
A10: V43 | B10: 40773 | C10: A | D10: 0.15 | E10: 0.12 | F10: SA | G10: 100 | H10: 0.52 | I10: 0.16 | J10: SA | K10: 100 | L10: 1 | M10: 0.15 | N10: SA | O10: 100 | P10: 1.25 | Q10: 0.24 | R10: SA | S10: 100 | T10: *1 | X10: 0 | Y10: 0 | Z10: 2 | AA10: 0 | AB10: 1 | AC10: 1 | AD10: 0 | AE10: 0 | AF10: 55 | AG10: 1.78 | AH10: 0.24 | AI10: 0.04 | AJ10: 0.17 | AK10: 1.97 | AL10: SA | AM10: GC | AN10: GC | AO10: SA | AP10: SA
A11: V42 | B11: 40779 | C11: D | D11: 0.22 | E11: 0.1 | F11: GC | G11: 50 | H11: 0.32 | I11: 0.077 | J11: GB | K11: 10 | L11: 0.47 | M11: 0.11 | N11: CB | O11: 10 | P11: 0.68 | Q11: 0.04 | R11: WD | S11: 10 | T11: 0.97 | U11: 0.04 | V11: SA | W11: 100 | X11: 0 | Y11: 0 | Z11: 4 | AA11: 0 | AB11: 0 | AC11: 0 | AD11: 0 | AE11: 0.22 | AF11: 0.4 | AG11: 0.96 | AH11: 0.13 | AI11: 0.24 | AJ11: 0.1 | AK11: 0.98 | AL11: CB | AM11: GF | AN11: GF | AO11: GF | AP11: CB
A12: V42 | B12: 40779 | C12: E | D12: 0.2 | E12: 0.11 | F12: SA | G12: 100 | H12: 0.31 | I12: 20 | J12: SA | K12: 100 | L12: 0.12 | M12: 0.19 | N12: GF | O12: 100 | P12: 0.9 | Q12: 0.13 | R12: SA | S12: 100 | T12: 0.12 | U12: 0.04 | V12: SA | W12: 100 | X12: 0 | Y12: 0 | Z12: 0 | AA12: 0 | AB12: 1 | AC12: 0 | AD12: 0 | AE12: 0 | AF12: 0.02 | AG12: 1.33 | AH12: 0.2 | AI12: 0.26 | AJ12: 0.26 | AK12: 0.84 | AL12: GF | AM12: GG | AN12: GC | AO12: GF | AP12: SA
A13: V42 | B13: 40779 | C13: A | D13: 0.1 | E13: 0.18 | F13: GC | G13: 10 | H13: 0.3 | I13: 0.04 | J13: LB | K13: 80 | L13: 0.6 | M13: 0.13 | N13: GC | O13: 20 | P13: 1 | Q13: 0.13 | R13: SA | S13: 100 | T13: 1.3 | U13: 0.19 | V13: SA | W13: 100 | X13: 0 | Y13: 0 | Z13: 4 | AA13: 6 | AB13: 21 | AC13: 21 | AD13: 8 | AE13: 10 | AF13: 0 | AG13: 1.45 | AH13: 0.16 | AI13: 0.48
A14: V42 | B14: 40779 | C14: B | D14: 0.2 | E14: 0.1 | F14: GF | G14: 50 | H14: 0.4 | I14: 0.12 | J14: GF | K14: 20 | L14: 0.58 | M14: 0.11 | N14: CB | O14: 20 | P14: 0.8 | Q14: 0.15 | R14: GC | S14: 20 | T14: 1 | U14: 0.17 | V14: GC | W14: 70 | X14: 0 | Y14: 0 | Z14: 4 | AA14: 0 | AB14: 1 | AC14: 1 | AD14: 1 | AE14: 0.18 | AF14: 0.06 | AG14: 1.16 | AH14: 0.19 | AI14: 0.63 | AJ14: 0.19 | AK14: 0.68 | AL14: SB | AM14: SB | AN14: SB | AO14: CB | AP14: GC | AY14: *3M of reach unsampleable due to vegetation
A15: V42 | B15: 40779 | C15: F | D15: 0.2 | E15: 0.22 | F15: GC | G15: 20 | H15: 0.3 | I15: 0.19 | J15: GC | K15: 20 | L15: 0.6 | M15: 0.2 | N15: GC | O15: 50 | P15: 0.9 | Q15: 0.07 | R15: SB | S15: 80 | T15: 1.08 | U15: 0.1 | V15: SB | W15: 80 | X15: 0 | Y15: 0 | Z15: 4 | AA15: 2 | AB15: 7 | AC15: 8 | AD15: 1 | AE15: 0 | AF15: 12 | AG15: 1.32 | AH15: 0.2 | AI15: 0.15 | AJ15: 0.15 | AK15: 1.06 | AL15: GF | AM15: GF | AN15: GC | AO15: GC | AP15: CB | AY15: Not enough sampleable creek available. No site G
A16: V42 | B16: 40779 | C16: C | D16: 0.15 | E16: 0.09 | F16: SA | G16: 100 | H16: 0.3 | I16: 0.09 | J16: GF | K16: 50 | L16: 0.62 | M16: 0.15 | N16: GC | O16: 10 | P16: 0.9 | Q16: 0.13 | R16: SA | S16: 100 | T16: 1.15 | U16: 0.14 | V16: GF | W16: 50 | X16: 0 | Y16: 0 | Z16: 0 | AA16: 0 | AB16: 0 | AC16: 1 | AD16: 0 | AE16: 0 | AF16: 0 | AG16: 1.26 | AH16: 0.19 | AI16: 0.61 | AJ16: 0.23 | AK16: 1.11 | AL16: SA | AM16: GF | AN16: GF | AO16: GC | AP16: SA
A17: V26 | B17: 40767 | C17: A | D17: 0.25 | E17: 0.05 | F17: GC | G17: 0 | H17: 0.42 | I17: 0.06 | J17: GC | K17: 20 | L17: 0.72 | M17: 0.07 | N17: GC | O17: 20 | P17: 1 | Q17: 0.08 | R17: SA | S17: 100 | T17: 1.16 | U17: 0.06 | V17: SA | W17: 100 | X17: 0 | Y17: 3 | Z17: 1 | AA17: 33 | AB17: 36 | AC17: 37 | AD17: 37 | AE17: 0 | AF17: 0 | AG17: 1.26 | AH17: 0.09 | AI17: 0.25 | AJ17: 0.014 | AK17: 1.25 | AL17: SA | AM17: GC | AN17: GC | AO17: SA | AP17: GC | AQ17: AB | AR17: 1.47 | AS17: 1.47 | AT17: 0.22 | AY17: New densiometers, max count 37
A18: V26 | B18: 40767 | C18: B | D18: 0.2 | E18: 0.05 | F18: GC | G18: 50 | H18: 0.36 | I18: 0.06 | J18: GC | K18: 0 | L18: 0.57 | M18: 0.09 | N18: GC | O18: 0 | P18: 0.75 | Q18: 0.06 | R18: GC | S18: 50 | T18: 1 | U18: 0.06 | V18: CB | W18: 50 | X18: 0 | Y18: 2 | Z18: 3 | AA18: 34 | AB18: 11 | AC18: 25 | AD18: 27 | AE18: 0.014 | AF18: 0.09 | AG18: 1.14 | AH18: 0.09 | AI18: 0.4 | AJ18: 0.12 | AK18: 0.75 | AL18: SA | AM18: GC | AN18: GC | AO18: GC | AP18: GC
A19: V26 | B19: 40767 | C19: C | D19: 0.32 | E19: 0.09 | F19: SA | G19: 100 | H19: 0.41 | I19: 0.1 | J19: SA | K19: 100 | L19: 0.55 | M19: 0.09 | N19: SA | O19: 100 | P19: 0.79 | Q19: 0.06 | R19: SA | S19: 100 | T19: 1 | U19: 0.01 | V19: SA | W19: 100 | X19: 0 | Y19: 0 | Z19: 2 | AA19: 2 | AB19: 0 | AC19: 0 | AD19: 9 | AE19: 0.22 | AF19: 0 | AG19: 1.12 | AH19: 0.1 | AI19: 0.24 | AJ19: 0.44 | AK19: 1 | AL19: SA | AM19: SA | AN19: GC | AO19: GF | AP19: GF | AU19: CD | AV19: .1-.3 | AW19: 5-15.0 | AX19: 1
A20: V26 | B20: 40767 | C20: D | D20: 0.13 | E20: 0.04 | F20: SA | G20: 100 | H20: 0.36 | I20: 0.05 | J20: SA | K20: 100 | L20: 0.5 | M20: 0.1 | N20: GC | O20: 0 | P20: 0.61 | Q20: 0 | R20: GC | S20: *3 | T20: 0.7 | V20: SA | W20: 100 | X20: 0 | Y20: 1 | Z20: 3 | AA20: 18 | AB20: 21 | AC20: 11 | AD20: 37 | AE20: 0 | AF20: 0.48 | AG20: 0.83 | AH20: 0.09 | AI20: 0.38 | AJ20: 0.24 | AK20: 1.45 | AL20: SA | AM20: SA | AN20: SA | AO20: SA | AP20: SA | AY20: *3: Undercut, could not get depth measurements
A21: V26 | B21: 40767 | C21: E | D21: 0.15 | E21: 0.2 | F21: SA | G21: 100 | H21: 0.3 | I21: 0.2 | J21: SA | K21: 100 | L21: 0.52 | M21: 0.15 | N21: SA | O21: 100 | P21: 0.77 | Q21: 0.1 | R21: SA | S21: 100 | T21: 1 | U21: 0.06 | V21: SA | W21: 100 | X21: 0 | Y21: 0 | Z21: 6 | AA21: 19 | AB21: 37 | AC21: 37 | AD21: 37 | AE21: 0 | AF21: 0 | AG21: 1.29 | AH21: 0.24 | AI21: 0.02 | AJ21: 0.13 | AK21: 1.12 | AL21: SA | AM21: GC | AN21: CB | AO21: GC | AP21: CB
A22: V26 | B22: 40767 | C22: F | D22: 0.07 | E22: 0.01 | F22: CB | G22: 10 | H22: 0.18 | I22: 0.05 | J22: CB | K22: 30 | L22: 0.3 | M22: 0.07 | N22: CB | O22: 50 | P22: 0.46 | Q22: 0.01 | R22: CB | S22: 10 | T22: 0.62 | U22: 0.03 | V22: GC | W22: 0 | X22: 0 | Y22: 1 | Z22: 4 | AA22: 37 | AB22: 37 | AC22: 37 | AD22: 37 | AE22: 0 | AF22: 0 | AG22: 0.7 | AH22: 0.09 | AI22: 0.47 | AJ22: 0.14 | AK22: 1.14 | AL22: SA | AM22: GC | AN22: GC | AO22: CB | AP22: SA
A23: V26 | B23: 40767 | C23: G | D23: 0.34 | E23: 0.1 | F23: SA | G23: 100 | H23: 0.65 | I23: 0.09 | J23: SA | K23: 100 | L23: 0.96 | M23: 0.09 | N23: GF | O23: 0 | P23: 1.19 | Q23: 0.05 | R23: SA | S23: 100 | T23: 1.4 | U23: 0.02 | V23: SA | W23: 100 | X23: 0 | Y23: 0 | Z23: 2 | AA23: 25 | AB23: 12 | AC23: 10 | AD23: 15 | AE23: 0.2 | AF23: 0 | AG23: 1.57 | AH23: 0.1 | AI23: 0.36
A24: V30 | B24: 40767 | C24: A | D24: 0.2 | E24: 0.13 | F24: LB | G24: 50 | H24: 0.4 | I24: 0.14 | J24: SB | K24: 30 | L24: 0.8 | M24: 0.16 | N24: LB | O24: 40 | P24: 0.13 | Q24: 0.1 | R24: SB | S24: 30 | T24: 0.14 | U24: 0.1 | V24: SB | W24: 30 | X24: 0 | Y24: 0 | Z24: 3 | AA24: 24 | AB24: 37 | AC24: 12 | AD24: 31 | AE24: 0.31 | AF24: 0.11 | AG24: 1.66 | AH24: 1.6 | AI24: 0*4 | AJ24: 0.9 | AK24: 1.42 | AL24: SB | AM24: WD | AN24: SB | AO24: CB | AP24: CB | AU24: AB | AV24: .1-.3 | AW24: 1.5-5 | AX24: 3 | AY24: *4: Flow is visible but could not detect behind boulder in transect
A25: V30 | B25: 40767 | C25: B | D25: 0.2 | E25: 0.17 | F25: FN | G25: 100 | H25: 0.34 | I25: 0.14 | J25: SB | K25: 50 | L25: 0.54 | M25: 0.16 | N25: SB | O25: 20 | P25: 0.75 | Q25: 0.04 | R25: SB | S25: 60 | T25: 0.96 | U25: 0.03 | V25: SB | W25: 65 | X25: 0 | Y25: 0 | Z25: 3 | AA25: 11 | AB25: 8 | AC25: 14 | AD25: 24 | AE25: 0.18 | AF25: 0.12 | AG25: 1.11 | AH25: 0.17 | AI25: 0.01 | AJ25: 0.21 | AK25: 0.65 | AL25: CB | AM25: CB | AN25: CB | AO25: CB | AP25: SA
A26: V30 | B26: 40767 | C26: C | D26: 0.38 | E26: 0.05 | F26: FN | G26: 100 | H26: 0.2 | I26: 0.085 | J26: FN | K26: 100 | L26: 0.1 | M26: 0.08 | N26: FN | O26: 100 | P26: 0.05 | Q26: 8 | R26: FN | S26: 100 | T26: 0.01 | U26: 0.05 | V26: FN | W26: 100 | X26: 0 | Y26: 0 | Z26: 3 | AA26: 0 | AB26: 0 | AC26: 0 | AD26: 0 | AE26: 0 | AF26: 0 | AG26: 0.43 | AH26: 0.13 | AI26: 0.05 | AJ26: 0.25 | AK26: 1 | AL26: SB | AM26: FN | AN26: FN | AO26: FN | AP26: FN | AU26: CD | AV26: .1-.3 | AW26: 1.5-5 | AX26: 2
A27: V30 | B27: 40767 | C27: D | D27: 1.23 | E27: 0.31 | F27: FN | G27: 100 | H27: 1 | I27: 0.42 | J27: FN | K27: 100 | L27: 0.75 | M27: 0.47 | N27: FN | O27: 100 | P27: 0.5 | Q27: 0.17 | R27: SB | S27: 30 | T27: 0.25 | U27: 0 | V27: SB | W27: 30 | X27: 0 | Y27: 0 | Z27: 3 | AA27: 0 | AB27: 0 | AC27: 0 | AD27: 0 | AE27: 0 | AF27: 0.21 | AG27: 1.5 | AH27: 0.5 | AI27: 0 | AJ27: 0.21 | AK27: 0.75 | AL27: FN | AM27: FN | AN27: SB | AO27: SB | AP27: SB
A28: V30 | B28: 40767 | C28: E | D28: 0.8 | E28: 0.06 | F28: FN | G28: 100 | H28: 0.66 | I28: 0.16 | J28: SA | K28: 100 | L28: 0.45 | M28: 0.26 | N28: FN | O28: 100 | P28: 0.3 | Q28: 0.005 | R28: FN | S28: 100 | T28: 0.13 | U28: 0.05 | V28: FN | W28: 100 | X28: 0 | Y28: 0 | Z28: 3 | AA28: 13 | AB28: 6 | AC28: 6 | AD28: 4 | AE28: 0.14 | AF28: 0 | AG28: 0.83 | AH28: 0.26 | AI28: 0.05 | AJ28: 0.15 | AK28: 0.93 | AL28: FN | AM28: FN | AN28: WD | AO28: SA | AP28: SB
A29: V30 | B29: 40767 | C29: F | D29: 0.2 | E29: 0.05 | F29: SA | G29: 100 | H29: 0.4 | I29: 0.01 | J29: SA | K29: 100 | L29: 0.55 | M29: 0.06 | N29: SA | O29: 100 | P29: 0.8 | Q29: 0.03 | R29: CB | S29: 50 | T29: 0.95 | U29: 0.04 | V29: CB | W29: 50 | X29: 0 | Y29: 0 | Z29: 3 | AA29: 33 | AB29: 13 | AC29: 18 | AD29: 4 | AE29: 0 | AF29: 0 | AG29: 0.94 | AH29: 0.11 | AI29: 0.18 | AJ29: 0.19 | AK29: 1.07 | AL29: FN | AM29: CB | AN29: CB | AO29: FN | AP29: FN
A30: V30 | B30: 40767 | C30: G | D30: 0.1 | E30: 0.03 | F30: CB | G30: 40 | H30: 0.2 | I30: 0.06 | J30: FN | K30: 100 | L30: 0.36 | M30: 0.09 | N30: GC | O30: 40 | P30: 0.66 | Q30: 0.07 | R30: FN | S30: 100 | T30: 0.7 | U30: 0.06 | V30: FN | W30: 100 | X30: 0 | Y30: 0 | Z30: 3 | AA30: 5 | AB30: 20 | AC30: 10 | AD30: 5 | AE30: 0.09 | AF30: 0.21 | AG30: 0.76 | AH30: 0.12 | AI30: 0.05
A31: V24 | B31: 40765 | C31: D | D31: 0.2 | E31: 0.05 | F31: SA | G31: 100 | H31: 0.4 | I31: 0.03 | J31: SA | K31: 100 | L31: 0.6 | M31: 0.05 | N31: GF | O31: 40 | P31: 0.8 | Q31: 0.07 | R31: GF | S31: 30 | T31: 1 | U31: 0.08 | V31: GF | W31: 50 | X31: 0 | Y31: 0 | Z31: 4 | AA31: 1 | AB31: 4 | AC31: 3 | AD31: 10 | AE31: 0.23 | AF31: 0 | AG31: 1.4 | AH31: 0.09 | AI31: 0.2 | AJ31: 0.12 | AK31: 0.104 | AL31: SA | AM31: GC | AN31: SA | AO31: SA | AP31: SA | AQ31: DE | AR31: 0.86 | AS31: 1.42 | AT31: 0.23
A32: V24 | B32: 40765 | AQ32: DE | AR32: 1.67 | AS32: 2.64 | AT32: 0.23
A33: V24 | B33: 40765 | C33: A | D33: 0.2 | E33: 0.12 | F33: GC | G33: 0 | H33: 0.3 | I33: 0.08 | J33: GF | K33: 0 | L33: 0.43 | M33: 0.05 | N33: SA | O33: 100 | P33: 0.6 | Q33: 0.03 | R33: SA | S33: 100 | T33: 0.8 | U33: 0.01 | V33: SA | W33: 100 | X33: 0 | Y33: 0 | Z33: 4 | AA33: 3 | AB33: 17 | AC33: 8 | AD33: 7 | AE33: 0.19 | AF33: 0 | AG33: 0.85 | AH33: 0.13 | AI33: 0.41 | AJ33: 0.08 | AK33: 0.6 | AL33: GC | AM33: GF | AN33: GF | AO33: GF | AP33: GF | AY33: Stream heavily vegetated, often subsurface or overgrown with willow and grass
A34: V24 | B34: 40765 | C34: C | D34: 0.16 | E34: 0.03 | F34: SA | G34: 100 | H34: 0.34 | I34: 0.12 | J34: GF | K34: 10 | L34: 0.7 | M34: 0.06 | N34: GF | O34: 10 | P34: 1 | Q34: 0.02 | R34: GF | S34: 10 | T34: 1.2 | U34: 0.02 | V34: GF | W34: 0 | X34: 0 | Y34: 0 | Z34: 3 | AA34: 5 | AB34: 4 | AC34: 0 | AD34: 2 | AE34: 0 | AF34: 0 | AG34: 1.5 | AH34: 0.11 | AI34: 0.29 | AJ34: 0.04 | AK34: 1.16 | AL34: GF | AM34: GF | AN34: GF | AO34: GF | AP34: GC | AQ34: BC | AR34: 1.86 | AS34: 1.4 | AT34: 0.36
A35: V24 | B35: 40765 | C35: B | D35: 0.2 | E35: 0.03 | F35: SA | G35: 100 | H35: 0.4 | I35: 0.04 | J35: GF | K35: 30 | L35: 0.6 | M35: 0.145 | N35: GF | O35: 10 | P35: 0.8 | Q35: 0.08 | R35: GF | S35: 10 | T35: 1 | U35: 0.05 | V35: SA | W35: 100 | X35: 0 | Y35: 0 | Z35: 4 | AA35: 2 | AB35: 3 | AC35: 5 | AD35: 6 | AE35: 0 | AF35: 0.34 | AG35: 1.13 | AH35: 0.08 | AI35: 0.09 | AJ35: 0.36 | AK35: 1.4 | AL35: SA | AM35: SA | AN35: GF | AO35: SA | AP35: SA
A36: V24 | B36: 40765 | C36: E | D36: 0.1 | E36: 0.08 | F36: SA | G36: 100 | H36: 0.19 | I36: 0.15 | J36: SA | K36: 100 | L36: 0.3 | M36: 0.17 | N36: SA | O36: 100 | P36: 0.4 | Q36: 0.2 | R36: SA | S36: 100 | T36: 0.48 | U36: 0.21 | V36: GC | W36: 0 | X36: 0 | Y36: 0 | Z36: 3 | AA36: 2 | AB36: 3 | AC36: 0 | AD36: 8 | AE36: 0 | AF36: 0 | AG36: 0.54 | AH36: 0.19 | AI36: 0.23 | AJ36: 0.15 | AK36: 0.79 | AL36: SA | AM36: GC | AN36: GC | AO36: SA | AP36: SA
A37: V24 | B37: 40765 | C37: F | D37: 0.2 | E37: 0.09 | F37: SA | G37: 100 | H37: 0.37 | I37: 10 | J37: GC | K37: 0 | L37: 0.53 | M37: 0.08 | N37: GC | O37: 50 | P37: 0.7 | Q37: 0.07 | R37: SA | S37: 100 | T37: 0.84 | U37: 0.07 | V37: GC | W37: 0 | X37: 0 | Y37: 0 | Z37: 4 | AA37: 1 | AB37: 2 | AC37: 4 | AD37: 12 | AE37: 0 | AF37: 0.25 | AG37: 0.91 | AH37: 0.11 | AI37: 0.05 | AJ37: 0.15 | AK37: 1 | AL37: SA | AM37: SA | AN37: GC | AO37: SA | AP37: SA | AQ37: FG | AR37: 1.9 | AS37: 1.44 | AT37: 0.23
A38: V24 | B38: 40765 | C38: G | D38: 0.1 | E38: 0.03 | F38: GF | G38: 0 | H38: 0.3 | I38: 0.05 | J38: GC | K38: 0 | L38: 0.5 | M38: 0.06 | N38: GC | O38: 0 | P38: 0.7 | Q38: 0.07 | R38: GC | S38: 0 | T38: 0.86 | U38: 0.05 | V38: GC | W38: 0 | X38: 0 | Y38: 0 | Z38: 2 | AA38: 0 | AB38: 0 | AC38: 0 | AD38: 11 | AE38: 0 | AF38: 0.3 | AG38: 1 | AH38: 0.06 | AI38: 0.46
A39: V25 | B39: 40764 | C39: D | D39: 0.3 | E39: 0.07 | F39: SA | G39: 100 | H39: 0.7 | I39: 0.1 | J39: SA | K39: 100 | L39: 1.2 | M39: 0.13 | N39: GC | O39: 50 | P39: 1.7 | Q39: 0.15 | R39: SA | S39: 100 | T39: 2.06 | U39: 0.14 | V39: SA | W39: 100 | X39: 1 | Y39: 1 | Z39: 0 | AA39: 1 | AB39: 3 | AC39: 6 | AD39: 2 | AE39: 0 | AF39: 0 | AG39: 2.19 | AH39: 0.015 | AI39: 0.18 | AJ39: 0.13 | AK39: 2.45 | AL39: GC | AM39: CB | AN39: GF | AO39: GF | AP39: SA
A40: V25 | B40: 40764 | C40: E | D40: 0.19 | E40: 0.09 | F40: SA | G40: 100 | H40: 0.4 | I40: 0.12 | J40: SA | K40: 100 | L40: 0.7 | M40: 0.16 | N40: SA | O40: 100 | P40: 1.14 | Q40: 0.14 | R40: GC | S40: 30 | T40: 1.7 | U40: 0.13 | V40: SA | W40: 100 | X40: 0 | Y40: 0 | Z40: 2 | AA40: 4 | AB40: 4 | AC40: 5 | AD40: 3 | AE40: 0 | AF40: 0 | AG40: 1.92 | AH40: 0.18 | AI40: 0.17 | AJ40: 0.16 | AK40: 1.24 | AL40: SA | AM40: GF | AN40: CB | AO40: GC | AP40: GC
...

Sheet Form4-WaterDischarge
D1: Stream Discharge
A2: Site ID | B2: Date | C2: Time (HH:MM) | D2: Location (nearest transect) | E2: Dist from bank (cm) | F2: Depth (cm) | G2: Velocity (m/s) | H2: Water samples (number filtered & unfil.) | I2: Comment
A3: V43 | B3: 40779 | E3: 30 | F3: 7 | G3: 0.2 | I3: *No data sheet
A4: V42 | B4: 40773 | E4: 42 | F4: 7 | G4: 0.27 | H4: 2EA
A5: V42 | B5: 40773 | E5: 54 | F5: 8 | G5: 0.11 | H5: 2EA
A6: V42 | B6: 40773 | E6: 66 | F6: 9 | G6: 0.17 | H6: 2EA
A7: V42 | B7: 40773 | E7: 78 | F7: 9 | G7: 0.13 | H7: 2EA
A8: V42 | B8: 40773 | E8: 90 | F8: 9 | G8: 0.05 | H8: 2EA
A9: V42 | B9: 40773 | E9: 102 | F9: 8 | G9: 0.04 | H9: 2EA
A10: V42 | B10: 40773 | E10: 120 | F10: 7 | G10: 0.07 | H10: 2EA
A11: V42 | B11: 40773 | E11: 132 | F11: 6 | G11: 0.09 | H11: 2EA
A12: V42 | B12: 40773 | E12: 144 | F12: 45 | G12: 0.01 | H12: 2EA
A13: V26 | B13: 40767 | C13: 0.60416667 | D13: C | E13: 11 | F13: 5.5 | G13: 0 | H13: 2EA
A14: V26 | B14: 40767 | C14: 0.60416667 | D14: C | E14: 22 | F14: 7 | G14: 0.12 | H14: 2EA
A15: V26 | B15: 40767 | C15: 0.60416667 | D15: C | E15: 33 | F15: 9 | G15: 0.16 | H15: 2EA
A16: V26 | B16: 40767 | C16: 0.60416667 | D16: C | E16: 44 | F16: 8 | G16: 0.17 | H16: 2EA
A17: V26 | B17: 40767 | C17: 0.60416667 | D17: C | E17: 55 | F17: 12 | G17: 0.12 | H17: 2EA
A18: V26 | B18: 40767 | C18: 0.60416667 | D18: C | E18: 66 | F18: 12 | G18: 0.13 | H18: 2EA
A19: V26 | B19: 40767 | C19: 0.60416667 | D19: C | E19: 77 | F19: 11 | G19: 0.12 | H19: 2EA
A20: V26 | B20: 40767 | C20: 0.60416667 | D20: C | E20: 88 | F20: 10 | G20: 0.09 | H20: 2EA
A21: V26 | B21: 40767 | C21: 0.60416667 | D21: C | E21: 99 | F21: 6 | G21: 0 | H21: 2EA
A22: V26 | B22: 40767 | C22: 0.60416667 | D22: C | E22: 111 | F22: 0 | G22: 0 | H22: 2EA
A23: V30 | B23: 40767 | C23: 1430 | E23: 5 | F23: 1 | G23: 0 | H23: 2EA
A24: V30 | B24: 40767 | C24: 1430 | E24: 1 | F24: 5 | G24: 0.16 | H24: 2EA
A25: V30 | B25: 40767 | C25: 1430 | E25: 16 | F25: 6 | G25: 0.16 | H25: 2EA
A26: V30 | B26: 40767 | C26: 1430 | E26: 22 | F26: 6 | G26: 0.12 | H26: 2EA
A27: V30 | B27: 40767 | C27: 1430 | E27: 31 | F27: 7 | G27: 0.15 | H27: 2EA
A28: V30 | B28: 40767 | C28: 1430 | E28: 36 | F28: 4 | G28: 0 | H28: 2EA
A29: V30 | B29: 40767 | C29: 1430 | E29: 4 | F29: 1 | G29: 0 | H29: 2EA
A30: V24 | B30: 40771 | C30: 1232 | D30: D | E30: 12 | F30: 3 | G30: 0 | H30: 2EA
A31: V24 | B31: 40771 | C31: 1232 | D31: D | E31: 24 | F31: 10 | G31: 0.12 | H31: 2EA
A32: V24 | B32: 40771 | C32: 1232 | D32: D | E32: 36 | F32: 20 | G32: 0.17 | H32: 2EA
A33: V24 | B33: 40771 | C33: 1232 | D33: D | E33: 48 | F33: 40 | G33: 0.19 | H33: 2EA
A34: V24 | B34: 40771 | C34: 1232 | D34: D | E34: 60 | F34: 30 | G34: 0.17 | H34: 2EA
A35: V24 | B35: 40771 | C35: 1232 | D35: D | E35: 72 | F35: 30 | G35: 0.14 | H35: 2EA
A36: V24 | B36: 40771 | C36: 1232 | D36: D | E36: 84 | F36: 20 | G36: 0.13 | H36: 2EA
A37: V24 | B37: 40771 | C37: 1232 | D37: D | E37: 96 | F37: 10 | G37: 0.1 | H37: 2EA
A38: V24 | B38: 40771 | C38: 1232 | D38: D | E38: 108 | F38: 4 | G38: 0 | H38: 2EA
A39: V24 | B39: 40771 | C39: 1232 | D39: D | E39: 112 | F39: 1 | G39: 0 | H39: 2EA
A40: V25 | B40: 40764 | C40: 1034 | E40: 5 | F40: =0.2*12*2.54 -> 6.096 | G40: 0 | H40: 2EA
...

Sheet Sheet1
